Workbook

Sheet 2022
B2: Expense Category | C2: Expense Type | D2: Jan | E2: Feb | F2: Mar | G2: Apr | H2: May | I2: Jun | J2: Jul | K2: Aug | L2: Sep | M2: Oct | N2: Nov | O2: Dec | P2: Total Yearly | Q2: Expense Category Wise Yearly Total
B3: Essential Living | C3: Dmart | D3: 0 | E3: 0 | F3: 0 | G3: 0 | H3: 0 | I3: 0 | J3: 0 | K3: 0 | L3: 0 | M3: 4500 | N3: 985 | O3: 5000 | P3: =SUM(D3:O3) -> 10485 | Q3: =SUM(P3:P15) -> 117831
C4: Electricity | D4: 0 | E4: 0 | F4: 0 | G4: 0 | H4: 0 | I4: 0 | J4: 0 | K4: 0 | L4: 390 | M4: 450 | N4: 810 | O4: 750 | P4: =SUM(D4:O4) -> 2400
C5: Fuel | D5: 0 | E5: 0 | F5: 0 | G5: 0 | H5: 0 | I5: 0 | J5: 0 | K5: 0 | L5: 0 | M5: 0 | N5: 0 | O5: 1500 | P5: =SUM(D5:O5) -> 1500
C6: Gas | D6: 0 | E6: 0 | F6: 0 | G6: 0 | H6: 0 | I6: 0 | J6: 0 | K6: 0 | L6: 0 | M6: 0 | N6: 1056 | O6: 1056 | P6: =SUM(D6:O6) -> 2112
C7: Groceries | D7: 0 | E7: 0 | F7: 0 | G7: 0 | H7: 0 | I7: 0 | J7: 0 | K7: 0 | L7: 0 | M7: 0 | N7: 1000 | O7: 800 | P7: =SUM(D7:O7) -> 1800
C8: House Help / Maid Salary | D8: 0 | E8: 0 | F8: 0 | G8: 0 | H8: 0 | I8: 0 | J8: 0 | K8: 0 | L8: 0 | M8: 0 | N8: 0 | O8: 0 | P8: =SUM(D8:O8) -> 0
C9: Internet / Wi-Fi | D9: 0 | E9: 0 | F9: 0 | G9: 0 | H9: 0 | I9: 0 | J9: 0 | K9: 0 | L9: 0 | M9: 0 | N9: 0 | O9: 0 | P9: =SUM(D9:O9) -> 0
C10: LIC | D10: 0 | E10: 0 | F10: 0 | G10: 0 | H10: 0 | I10: 0 | J10: 0 | K10: 0 | L10: 52065 | M10: 0 | N10: 0 | O10: 4715 | P10: =SUM(D10:O10) -> 56780
C11: Phone / Mobile Bill | D11: 0 | E11: 0 | F11: 0 | G11: 0 | H11: 0 | I11: 0 | J11: 0 | K11: 0 | L11: 155 | M11: 0 | N11: 1799 | O11: 0 | P11: =SUM(D11:O11) -> 1954
C12: Property Tax | D12: 0 | E12: 0 | F12: 0 | G12: 0 | H12: 0 | I12: 0 | J12: 0 | K12: 0 | L12: 0 | M12: 0 | N12: 0 | O12: 0 | P12: =SUM(D12:O12) -> 0
C13: Rent | D13: 0 | E13: 0 | F13: 0 | G13: 0 | H13: 0 | I13: 0 | J13: 0 | K13: 0 | L13: 7500 | M13: 7500 | N13: 7500 | O13: 7500 | P13: =SUM(D13:O13) -> 30000
C14: Term Plan | D14: 0 | E14: 0 | F14: 0 | G14: 0 | H14: 0 | I14: 0 | J14: 0 | K14: 0 | L14: 2700 | M14: 2760 | N14: 2670 | O14: 2670 | P14: =SUM(D14:O14) -> 10800
C15: Water Bill | D15: 0 | E15: 0 | F15: 0 | G15: 0 | H15: 0 | I15: 0 | J15: 0 | K15: 0 | L15: 0 | M15: 0 | N15: 0 | O15: 0 | P15: =SUM(D15:O15) -> 0
B16: Loans & Financial | C16: Credit Card Payments | D16: 0 | E16: 0 | F16: 0 | G16: 0 | H16: 0 | I16: 0 | J16: 0 | K16: 0 | L16: 10000 | M16: 0 | N16: 22280 | O16: 7400 | P16: =SUM(D16:O16) -> 39680 | Q16: =SUM(P16:P20) -> 292995
C17: Gold Loan | D17: 0 | E17: 0 | F17: 0 | G17: 0 | H17: 0 | I17: 0 | J17: 0 | K17: 0 | L17: 0 | M17: 0 | N17: 0 | O17: 0 | P17: =SUM(D17:O17) -> 0
C18: Home Loan EMI | D18: 0 | E18: 0 | F18: 0 | G18: 0 | H18: 0 | I18: 0 | J18: 0 | K18: 0 | L18: 19000 | M18: 19000 | N18: 20000 | O18: 20000 | P18: =SUM(D18:O18) -> 78000
C19: Money Returned to Friend/Family | D19: 0 | E19: 0 | F19: 0 | G19: 0 | H19: 0 | I19: 0 | J19: 0 | K19: 0 | L19: 21000 | M19: 100000 | N19: 54315 | O19: 0 | P19: =SUM(D19:O19) -> 175315
C20: Personal Loan | D20: 0 | E20: 0 | F20: 0 | G20: 0 | H20: 0 | I20: 0 | J20: 0 | K20: 0 | L20: 0 | M20: 0 | N20: 0 | O20: 0 | P20: =SUM(D20:O20) -> 0
B21: Family & Education | C21: Education Expenses (Sport material,Books, Uniforms, Shoes, Stationery, etc.) | D21: 0 | E21: 0 | F21: 0 | G21: 0 | H21: 0 | I21: 0 | J21: 0 | K21: 0 | L21: 0 | M21: 0 | N21: 0 | O21: 0 | P21: =SUM(D21:O21) -> 0 | Q21: =SUM(P21:P25) -> 58330
C22: Family Support | D22: 0 | E22: 0 | F22: 0 | G22: 0 | H22: 0 | I22: 0 | J22: 0 | K22: 0 | L22: 0 | M22: 0 | N22: 25000 | O22: 3000 | P22: =SUM(D22:O22) -> 28000
C23: Hobbies (Drawing, Bharatnatyam, etc.) | D23: 0 | E23: 0 | F23: 0 | G23: 0 | H23: 0 | I23: 0 | J23: 0 | K23: 0 | L23: 1000 | M23: 1000 | N23: 830 | O23: 1500 | P23: =SUM(D23:O23) -> 4330
C24: School Fees | D24: 0 | E24: 0 | F24: 0 | G24: 0 | H24: 0 | I24: 0 | J24: 0 | K24: 0 | L24: 0 | M24: 0 | N24: 15000 | O24: 0 | P24: =SUM(D24:O24) -> 15000
C25: Sports (Skating, Badminton, Cricket, Hockey) | D25: 0 | E25: 0 | F25: 0 | G25: 0 | H25: 0 | I25: 0 | J25: 0 | K25: 0 | L25: 3000 | M25: 0 | N25: 5000 | O25: 3000 | P25: =SUM(D25:O25) -> 11000
B26: Health & Medical | C26: Doctors | D26: 0 | E26: 0 | F26: 0 | G26: 0 | H26: 0 | I26: 0 | J26: 0 | K26: 0 | L26: 0 | M26: 0 | N26: 0 | O26: 0 | P26: =SUM(D26:O26) -> 0 | Q26: =SUM(P26:P27) -> 6500
C27: Medicine | D27: 0 | E27: 0 | F27: 0 | G27: 0 | H27: 0 | I27: 0 | J27: 0 | K27: 0 | L27: 0 | M27: 0 | N27: 0 | O27: 6500 | P27: =SUM(D27:O27) -> 6500
B28: Lifestyle & Personal | C28: Clothing | D28: 0 | E28: 0 | F28: 0 | G28: 0 | H28: 0 | I28: 0 | J28: 0 | K28: 0 | L28: 0 | M28: 0 | N28: 0 | O28: 1500 | P28: =SUM(D28:O28) -> 1500 | Q28: =SUM(P28:P35) -> 4920
C29: Dining Out | D29: 0 | E29: 0 | F29: 0 | G29: 0 | H29: 0 | I29: 0 | J29: 0 | K29: 0 | L29: 0 | M29: 0 | N29: 0 | O29: 1770 | P29: =SUM(D29:O29) -> 1770
C30: Gym | D30: 0 | E30: 0 | F30: 0 | G30: 0 | H30: 0 | I30: 0 | J30: 0 | K30: 0 | L30: 0 | M30: 0 | N30: 0 | O30: 0 | P30: =SUM(D30:O30) -> 0
C31: Hair / Cosmetics | D31: 0 | E31: 0 | F31: 0 | G31: 0 | H31: 0 | I31: 0 | J31: 0 | K31: 0 | L31: 0 | M31: 0 | N31: 0 | O31: 0 | P31: =SUM(D31:O31) -> 0
C32: Membership(Google,Netflix,Education,Youtube) | D32: 0 | E32: 0 | F32: 0 | G32: 0 | H32: 0 | I32: 0 | J32: 0 | K32: 0 | L32: 0 | M32: 0 | N32: 0 | O32: 0 | P32: =SUM(D32:O32) -> 0
C33: Movies | D33: 0 | E33: 0 | F33: 0 | G33: 0 | H33: 0 | I33: 0 | J33: 0 | K33: 0 | L33: 0 | M33: 0 | N33: 0 | O33: 0 | P33: =SUM(D33:O33) -> 0
C34: Other Expenses | D34: 0 | E34: 0 | F34: 0 | G34: 0 | H34: 0 | I34: 0 | J34: 0 | K34: 0 | L34: 0 | M34: 0 | N34: 0 | O34: 0 | P34: =SUM(D34:O34) -> 0
C35: Travel / Holiday Trips | D35: 0 | E35: 0 | F35: 0 | G35: 0 | H35: 0 | I35: 0 | J35: 0 | K35: 0 | L35: 0 | M35: 0 | N35: 0 | O35: 1650 | P35: =SUM(D35:O35) -> 1650
B36: Investments & Savings | C36: Gold Bhishi | D36: 0 | E36: 0 | F36: 0 | G36: 0 | H36: 0 | I36: 0 | J36: 0 | K36: 0 | L36: 0 | M36: 0 | N36: 0 | O36: 0 | P36: =SUM(D36:O36) -> 0 | Q36: =SUM(P36:P42) -> 12000
C37: IWish | D37: 0 | E37: 0 | F37: 0 | G37: 0 | H37: 0 | I37: 0 | J37: 0 | K37: 0 | L37: 0 | M37: 0 | N37: 0 | O37: 0 | P37: =SUM(D37:O37) -> 0
C38: Mutual Funds | D38: 0 | E38: 0 | F38: 0 | G38: 0 | H38: 0 | I38: 0 | J38: 0 | K38: 0 | L38: 0 | M38: 0 | N38: 0 | O38: 0 | P38: =SUM(D38:O38) -> 0
C39: Provident Fund | D39: 0 | E39: 0 | F39: 0 | G39: 0 | H39: 0 | I39: 0 | J39: 0 | K39: 0 | L39: 0 | M39: 0 | N39: 0 | O39: 0 | P39: =SUM(D39:O39) -> 0
C40: Post Office RD | D40: 0 | E40: 0 | F40: 0 | G40: 0 | H40: 0 | I40: 0 | J40: 0 | K40: 0 | L40: 0 | M40: 0 | N40: 0 | O40: 2000 | P40: =SUM(D40:O40) -> 2000
C41: Shares (Ashwini Shares) | D41: 0 | E41: 0 | F41: 0 | G41: 0 | H41: 0 | I41: 0 | J41: 0 | K41: 0 | L41: 0 | M41: 0 | N41: 0 | O41: 0 | P41: =SUM(D41:O41) -> 0
...

Sheet 2023
B2: Expense Category | C2: Expense Type | D2: Jan | E2: Feb | F2: Mar | G2: Apr | H2: May | I2: Jun | J2: Jul | K2: Aug | L2: Sep | M2: Oct | N2: Nov | O2: Dec | P2: Total Yearly | Q2: Expense Category Wise Yearly Total
B3: Essential Living | C3: Dmart | D3: 3432 | E3: 1000 | F3: 720 | G3: 2300 | H3: 2800 | I3: 2000 | J3: 5550 | K3: 2000 | L3: 6000 | M3: 5500 | N3: 5335 | O3: 3105 | P3: =SUM(D3:O3) -> 39742 | Q3: =SUM(P3:P15) -> 399379
C4: Electricity | D4: 808 | E4: 850 | F4: 700 | G4: 950 | H4: 1000 | I4: 1210 | J4: 1000 | K4: 1000 | L4: 900 | M4: 900 | N4: 1040 | O4: 910 | P4: =SUM(D4:O4) -> 11268
C5: Fuel | D5: 0 | E5: 0 | F5: 0 | G5: 1000 | H5: 1500 | I5: 0 | J5: 0 | K5: 0 | L5: 0 | M5: 2480 | N5: 2950 | O5: 2450 | P5: =SUM(D5:O5) -> 10380
C6: Gas | D6: 1056 | E6: 1056 | F6: 2212 | G6: 0 | H6: 1106 | I6: 0 | J6: 1106 | K6: 1812 | L6: 960 | M6: 960 | N6: 1812 | O6: 1812 | P6: =SUM(D6:O6) -> 13892
C7: Groceries | D7: 6230 | E7: 2312 | F7: 1124 | G7: 0 | H7: 1000 | I7: 0 | J7: 2800 | K7: 0 | L7: 0 | M7: 3701 | N7: 3103 | O7: 1731 | P7: =SUM(D7:O7) -> 22001
C8: House Help / Maid Salary | D8: 0 | E8: 0 | F8: 0 | G8: 0 | H8: 0 | I8: 0 | J8: 0 | K8: 0 | L8: 0 | M8: 0 | N8: 0 | O8: 0 | P8: =SUM(D8:O8) -> 0
C9: Internet / Wi-Fi | D9: 7200 | E9: 0 | F9: 0 | G9: 0 | H9: 0 | I9: 0 | J9: 0 | K9: 0 | L9: 0 | M9: 0 | N9: 0 | O9: 0 | P9: =SUM(D9:O9) -> 7200
C10: LIC | D10: 4715 | E10: 10780 | F10: 12036 | G10: 4715 | H10: 4715 | I10: 4715 | J10: 65259 | K10: 4715 | L10: 18101 | M10: 4915 | N10: 4715 | O10: 21359 | P10: =SUM(D10:O10) -> 160740
C11: Phone / Mobile Bill | D11: 0 | E11: 1799 | F11: 0 | G11: 0 | H11: 400 | I11: 0 | J11: 0 | K11: 0 | L11: 0 | M11: 380 | N11: 2399 | O11: 940 | P11: =SUM(D11:O11) -> 5918
C12: Property Tax | D12: 0 | E12: 0 | F12: 0 | G12: 0 | H12: 0 | I12: 0 | J12: 0 | K12: 0 | L12: 0 | M12: 0 | N12: 0 | O12: 0 | P12: =SUM(D12:O12) -> 0
C13: Rent | D13: 7500 | E13: 8000 | F13: 8000 | G13: 8000 | H13: 8000 | I13: 8000 | J13: 8000 | K13: 8000 | L13: 8000 | M13: 8000 | N13: 8000 | O13: 8000 | P13: =SUM(D13:O13) -> 95500
C14: Term Plan | D14: 2670 | E14: 2670 | F14: 2670 | G14: 2670 | H14: 2670 | I14: 2670 | J14: 2670 | K14: 2670 | L14: 2670 | M14: 2670 | N14: 2670 | O14: 2670 | P14: =SUM(D14:O14) -> 32040
C15: Water Bill | D15: 0 | E15: 0 | F15: 0 | G15: 0 | H15: 0 | I15: 0 | J15: 410 | K15: 0 | L15: 0 | M15: 288 | N15: 0 | O15: 0 | P15: =SUM(D15:O15) -> 698
B16: Loans & Financial | C16: Credit Card Payments | D16: 8010 | E16: 6435 | F16: 13800 | G16: 13900 | H16: 11600 | I16: 0 | J16: 65000 | K16: 31000 | L16: 21500 | M16: 22135 | N16: 13547 | O16: 16000 | P16: =SUM(D16:O16) -> 222927 | Q16: =SUM(P16:P20) -> 1492695
C17: Gold Loan | D17: 0 | E17: 80000 | F17: 60000 | G17: 25000 | H17: 0 | I17: 0 | J17: 216628 | K17: 0 | L17: 0 | M17: 0 | N17: 0 | O17: 0 | P17: =SUM(D17:O17) -> 381628
C18: Home Loan EMI | D18: 20000 | E18: 21000 | F18: 21000 | G18: 21000 | H18: 21000 | I18: 21000 | J18: 21000 | K18: 21000 | L18: 21000 | M18: 21000 | N18: 21000 | O18: 21000 | P18: =SUM(D18:O18) -> 251000
C19: Money Returned to Friend/Family | D19: 32510 | E19: 3700 | F19: 3075 | G19: 4500 | H19: 10500 | I19: 6500 | J19: 9850 | K19: 21000 | L19: 405000 | M19: 1500 | N19: 4005 | O19: 0 | P19: =SUM(D19:O19) -> 502140
C20: Personal Loan | D20: 0 | E20: 0 | F20: 0 | G20: 0 | H20: 0 | I20: 0 | J20: 0 | K20: 27000 | L20: 27000 | M20: 27000 | N20: 27000 | O20: 27000 | P20: =SUM(D20:O20) -> 135000
B21: Family & Education | C21: Education Expenses (Sport material,Books, Uniforms, Shoes, Stationery, etc.) | D21: 0 | E21: 0 | F21: 0 | G21: 0 | H21: 3200 | I21: 1575 | J21: 0 | K21: 0 | L21: 0 | M21: 0 | N21: 0 | O21: 0 | P21: =SUM(D21:O21) -> 4775 | Q21: =SUM(P21:P25) -> 140955
C22: Family Support | D22: 0 | E22: 5000 | F22: 0 | G22: 0 | H22: 0 | I22: 0 | J22: 0 | K22: 0 | L22: 10000 | M22: 0 | N22: 0 | O22: 0 | P22: =SUM(D22:O22) -> 15000
C23: Hobbies (Drawing, Bharatnatyam, etc.) | D23: 1000 | E23: 3500 | F23: 1500 | G23: 1000 | H23: 0 | I23: 0 | J23: 0 | K23: 0 | L23: 0 | M23: 1080 | N23: 1500 | O23: 1000 | P23: =SUM(D23:O23) -> 10580
C24: School Fees | D24: 0 | E24: 0 | F24: 0 | G24: 0 | H24: 0 | I24: 0 | J24: 30000 | K24: 0 | L24: 0 | M24: 10000 | N24: 0 | O24: 10000 | P24: =SUM(D24:O24) -> 50000
C25: Sports (Skating, Badminton, Cricket, Hockey) | D25: 3000 | E25: 3000 | F25: 6000 | G25: 6000 | H25: 3000 | I25: 8000 | J25: 12000 | K25: 0 | L25: 0 | M25: 11000 | N25: 6000 | O25: 2600 | P25: =SUM(D25:O25) -> 60600
B26: Health & Medical | C26: Doctors | D26: 0 | E26: 0 | F26: 0 | G26: 0 | H26: 0 | I26: 0 | J26: 0 | K26: 12000 | L26: 7500 | M26: 9000 | N26: 960 | O26: 0 | P26: =SUM(D26:O26) -> 29460 | Q26: =SUM(P26:P27) -> 62740
C27: Medicine | D27: 0 | E27: 0 | F27: 0 | G27: 0 | H27: 6500 | I27: 19000 | J27: 2450 | K27: 0 | L27: 850 | M27: 3700 | N27: 780 | O27: 0 | P27: =SUM(D27:O27) -> 33280
B28: Lifestyle & Personal | C28: Clothing | D28: 2297 | E28: 0 | F28: 0 | G28: 0 | H28: 0 | I28: 4100 | J28: 2200 | K28: 0 | L28: 0 | M28: 1200 | N28: 5610 | O28: 1000 | P28: =SUM(D28:O28) -> 16407 | Q28: =SUM(P28:P35) -> 47997
C29: Dining Out | D29: 0 | E29: 0 | F29: 0 | G29: 0 | H29: 0 | I29: 0 | J29: 0 | K29: 0 | L29: 0 | M29: 0 | N29: 3410 | O29: 3250 | P29: =SUM(D29:O29) -> 6660
C30: Gym | D30: 0 | E30: 0 | F30: 0 | G30: 0 | H30: 0 | I30: 0 | J30: 0 | K30: 0 | L30: 0 | M30: 0 | N30: 0 | O30: 0 | P30: =SUM(D30:O30) -> 0
C31: Hair / Cosmetics | D31: 200 | E31: 0 | F31: 0 | G31: 0 | H31: 0 | I31: 0 | J31: 0 | K31: 180 | L31: 0 | M31: 0 | N31: 0 | O31: 0 | P31: =SUM(D31:O31) -> 380
C32: Membership(Google,Netflix,Education,Youtube) | D32: 0 | E32: 0 | F32: 0 | G32: 0 | H32: 0 | I32: 0 | J32: 0 | K32: 0 | L32: 0 | M32: 0 | N32: 0 | O32: 1300 | P32: =SUM(D32:O32) -> 1300
C33: Movies | D33: 0 | E33: 0 | F33: 0 | G33: 0 | H33: 0 | I33: 0 | J33: 0 | K33: 0 | L33: 0 | M33: 0 | N33: 0 | O33: 0 | P33: =SUM(D33:O33) -> 0
C34: Other Expenses | D34: 0 | E34: 0 | F34: 0 | G34: 0 | H34: 0 | I34: 0 | J34: 1100 | K34: 0 | L34: 0 | M34: 2000 | N34: 0 | O34: 0 | P34: =SUM(D34:O34) -> 3100
C35: Travel / Holiday Trips | D35: 0 | E35: 0 | F35: 0 | G35: 0 | H35: 0 | I35: 0 | J35: 0 | K35: 3200 | L35: 1500 | M35: 6500 | N35: 2500 | O35: 6450 | P35: =SUM(D35:O35) -> 20150
B36: Investments & Savings | C36: Gold Bhishi | D36: 0 | E36: 0 | F36: 0 | G36: 0 | H36: 0 | I36: 0 | J36: 0 | K36: 0 | L36: 0 | M36: 0 | N36: 0 | O36: 0 | P36: =SUM(D36:O36) -> 0 | Q36: =SUM(P36:P42) -> 30000
C37: IWish | D37: 0 | E37: 0 | F37: 0 | G37: 0 | H37: 0 | I37: 0 | J37: 0 | K37: 0 | L37: 0 | M37: 0 | N37: 0 | O37: 0 | P37: =SUM(D37:O37) -> 0
C38: Mutual Funds | D38: 0 | E38: 0 | F38: 0 | G38: 0 | H38: 0 | I38: 0 | J38: 0 | K38: 0 | L38: 0 | M38: 0 | N38: 0 | O38: 0 | P38: =SUM(D38:O38) -> 0
C39: Provident Fund | D39: 0 | E39: 0 | F39: 0 | G39: 0 | H39: 0 | I39: 0 | J39: 0 | K39: 0 | L39: 0 | M39: 0 | N39: 0 | O39: 0 | P39: =SUM(D39:O39) -> 0
C40: Post Office RD | D40: 0 | E40: 0 | F40: 0 | G40: 0 | H40: 0 | I40: 0 | J40: 0 | K40: 0 | L40: 0 | M40: 0 | N40: 0 | O40: 0 | P40: =SUM(D40:O40) -> 0
C41: Shares (Ashwini Shares) | D41: 0 | E41: 0 | F41: 0 | G41: 0 | H41: 0 | I41: 0 | J41: 0 | K41: 0 | L41: 0 | M41: 0 | N41: 0 | O41: 0 | P41: =SUM(D41:O41) -> 0
...

Sheet 2024
B2: Expense Category | C2: Expense Type | D2: Jan | E2: Feb | F2: Mar | G2: Apr | H2: May | I2: Jun | J2: Jul | K2: Aug | L2: Sep | M2: Oct | N2: Nov | O2: Dec | P2: Total Yearly | Q2: Expense Category Wise Yearly Total
B3: Essential Living | C3: Dmart | D3: 3500 | E3: 1685 | F3: 2424 | G3: 12369 | H3: 1879 | I3: 0 | J3: 4400 | K3: 2800 | L3: 8565 | M3: 0 | N3: 2121 | O3: 0 | P3: =SUM(D3:O3) -> 39743 | Q3: =SUM(P3:P15) -> 536796
C4: Electricity | D4: 990 | E4: 930 | F4: 1060 | G4: 960 | H4: 520 | I4: 1340 | J4: 740 | K4: 630 | L4: 730 | M4: 0 | N4: 1600 | O4: 650 | P4: =SUM(D4:O4) -> 10150
C5: Fuel | D5: 2450 | E5: 2450 | F5: 2450 | G5: 2450 | H5: 2450 | I5: 2450 | J5: 2450 | K5: 2850 | L5: 2850 | M5: 2850 | N5: 2850 | O5: 2850 | P5: =SUM(D5:O5) -> 31400
C6: Gas | D6: 1812 | E6: 1000 | F6: 1612 | G6: 806 | H6: 806 | I6: 806 | J6: 1612 | K6: 806 | L6: 806 | M6: 1612 | N6: 1612 | O6: 806 | P6: =SUM(D6:O6) -> 14096
C7: Groceries | D7: 634 | E7: 2009 | F7: 1152 | G7: 5722 | H7: 1910 | I7: 2991 | J7: 6776 | K7: 3975 | L7: 1340 | M7: 4089 | N7: 2018 | O7: 1181 | P7: =SUM(D7:O7) -> 33797
C8: House Help / Maid Salary | D8: 0 | E8: 1750 | F8: 2000 | G8: 2000 | H8: 2000 | I8: 2000 | J8: 2000 | K8: 2000 | L8: 3500 | M8: 3500 | N8: 5000 | O8: 2000 | P8: =SUM(D8:O8) -> 27750
C9: Internet / Wi-Fi | D9: 0 | E9: 0 | F9: 7200 | G9: 0 | H9: 0 | I9: 0 | J9: 0 | K9: 0 | L9: 0 | M9: 0 | N9: 0 | O9: 0 | P9: =SUM(D9:O9) -> 7200
C10: LIC | D10: 4715 | E10: 4715 | F10: 17798 | G10: 4512 | H10: 20959 | I10: 48513 | J10: 4614 | K10: 10679 | L10: 11934 | M10: 4614 | N10: 36965 | O10: 4614 | P10: =SUM(D10:O10) -> 174632
C11: Phone / Mobile Bill | D11: 716 | E11: 1636 | F11: 0 | G11: 916 | H11: 180 | I11: 2406 | J11: 807 | K11: 688 | L11: 31641 | M11: 379 | N11: 3998 | O11: 249 | P11: =SUM(D11:O11) -> 43616
C12: Property Tax | D12: 0 | E12: 0 | F12: 0 | G12: 0 | H12: 13660 | I12: 0 | J12: 0 | K12: 0 | L12: 0 | M12: 0 | N12: 7736 | O12: 0 | P12: =SUM(D12:O12) -> 21396
C13: Rent | D13: 8000 | E13: 8000 | F13: 8000 | G13: 8000 | H13: 8500 | I13: 8500 | J13: 8500 | K13: 8500 | L13: 8500 | M13: 8500 | N13: 8500 | O13: 8500 | P13: =SUM(D13:O13) -> 100000
C14: Term Plan | D14: 2670 | E14: 2670 | F14: 2670 | G14: 2670 | H14: 2670 | I14: 2670 | J14: 2670 | K14: 2670 | L14: 2670 | M14: 2670 | N14: 2670 | O14: 2670 | P14: =SUM(D14:O14) -> 32040
C15: Water Bill | D15: 373 | E15: 0 | F15: 0 | G15: 333 | H15: 0 | I15: 0 | J15: 0 | K15: 0 | L15: 0 | M15: 270 | N15: 0 | O15: 0 | P15: =SUM(D15:O15) -> 976
B16: Loans & Financial | C16: Credit Card Payments | D16: 37566 | E16: 700 | F16: 45000 | G16: 110000 | H16: 64608 | I16: 37817 | J16: 3250 | K16: 0 | L16: 0 | M16: 32756 | N16: 147250 | O16: 0 | P16: =SUM(D16:O16) -> 478947 | Q16: =SUM(P16:P20) -> 1338265
C17: Gold Loan | D17: 0 | E17: 0 | F17: 0 | G17: 0 | H17: 0 | I17: 0 | J17: 0 | K17: 0 | L17: 0 | M17: 14300 | N17: 327089 | O17: 0 | P17: =SUM(D17:O17) -> 341389
C18: Home Loan EMI | D18: 21000 | E18: 21000 | F18: 21000 | G18: 21000 | H18: 21000 | I18: 21000 | J18: 21000 | K18: 21000 | L18: 21000 | M18: 21000 | N18: 19400 | O18: 18400 | P18: =SUM(D18:O18) -> 247800
C19: Money Returned to Friend/Family | D19: 0 | E19: 9400 | F19: 0 | G19: 0 | H19: 29079 | I19: 0 | J19: 0 | K19: 1450 | L19: 0 | M19: 1200 | N19: 40000 | O19: 0 | P19: =SUM(D19:O19) -> 81129
C20: Personal Loan | D20: 27000 | E20: 27000 | F20: 27000 | G20: 27000 | H20: 27000 | I20: 27000 | J20: 27000 | K20: 0 | L20: 0 | M20: 0 | N20: 0 | O20: 0 | P20: =SUM(D20:O20) -> 189000
B21: Family & Education | C21: Education Expenses (Sport material,Books, Uniforms, Shoes, Stationery, etc.) | D21: 0 | E21: 0 | F21: 0 | G21: 0 | H21: 3816 | I21: 0 | J21: 0 | K21: 0 | L21: 0 | M21: 0 | N21: 739 | O21: 0 | P21: =SUM(D21:O21) -> 4555 | Q21: =SUM(P21:P25) -> 256130
C22: Family Support | D22: 0 | E22: 0 | F22: 0 | G22: 0 | H22: 0 | I22: 5500 | J22: 0 | K22: 0 | L22: 0 | M22: 80000 | N22: 20000 | O22: 0 | P22: =SUM(D22:O22) -> 105500
C23: Hobbies (Drawing, Bharatnatyam, etc.) | D23: 1000 | E23: 1000 | F23: 1000 | G23: 0 | H23: 2800 | I23: 1000 | J23: 1350 | K23: 1000 | L23: 1000 | M23: 1000 | N23: 1000 | O23: 1000 | P23: =SUM(D23:O23) -> 13150
C24: School Fees | D24: 0 | E24: 0 | F24: 0 | G24: 0 | H24: 12000 | I24: 0 | J24: 0 | K24: 12000 | L24: 0 | M24: 0 | N24: 0 | O24: 0 | P24: =SUM(D24:O24) -> 24000
C25: Sports (Skating, Badminton, Cricket, Hockey) | D25: 11500 | E25: 19000 | F25: 7000 | G25: 7000 | H25: 8050 | I25: 10980 | J25: 8430 | K25: 13565 | L25: 7500 | M25: 5900 | N25: 5000 | O25: 5000 | P25: =SUM(D25:O25) -> 108925
B26: Health & Medical | C26: Doctors | D26: 0 | E26: 0 | F26: 8170 | G26: 8000 | H26: 0 | I26: 0 | J26: 1500 | K26: 19631 | L26: 8080 | M26: 6600 | N26: 0 | O26: 0 | P26: =SUM(D26:O26) -> 51981 | Q26: =SUM(P26:P27) -> 151778
C27: Medicine | D27: 0 | E27: 25511 | F27: 62000 | G27: 11546 | H27: 0 | I27: 0 | J27: 0 | K27: 300 | L27: 0 | M27: 440 | N27: 0 | O27: 0 | P27: =SUM(D27:O27) -> 99797
B28: Lifestyle & Personal | C28: Clothing | D28: 0 | E28: 0 | F28: 0 | G28: 12144 | H28: 2350 | I28: 4468 | J28: 4400 | K28: 2986 | L28: 5723 | M28: 6685 | N28: 7160 | O28: 2450 | P28: =SUM(D28:O28) -> 48366 | Q28: =SUM(P28:P35) -> 386163
C29: Dining Out | D29: 0 | E29: 0 | F29: 0 | G29: 4554 | H29: 1000 | I29: 5670 | J29: 650 | K29: 6070 | L29: 15289 | M29: 38241 | N29: 570 | O29: 16272 | P29: =SUM(D29:O29) -> 88316
C30: Gym | D30: 0 | E30: 0 | F30: 0 | G30: 0 | H30: 0 | I30: 0 | J30: 0 | K30: 0 | L30: 0 | M30: 0 | N30: 0 | O30: 0 | P30: =SUM(D30:O30) -> 0
C31: Hair / Cosmetics | D31: 0 | E31: 0 | F31: 0 | G31: 0 | H31: 0 | I31: 0 | J31: 0 | K31: 0 | L31: 0 | M31: 0 | N31: 0 | O31: 400 | P31: =SUM(D31:O31) -> 400
C32: Membership(Google,Netflix,Education,Youtube) | D32: 0 | E32: 0 | F32: 0 | G32: 0 | H32: 0 | I32: 0 | J32: 0 | K32: 3171 | L32: 3171 | M32: 199 | N32: 0 | O32: 0 | P32: =SUM(D32:O32) -> 6541
C33: Movies | D33: 0 | E33: 0 | F33: 0 | G33: 0 | H33: 0 | I33: 0 | J33: 0 | K33: 0 | L33: 0 | M33: 0 | N33: 0 | O33: 0 | P33: =SUM(D33:O33) -> 0
C34: Other Expenses | D34: 0 | E34: 0 | F34: 0 | G34: 1610 | H34: 0 | I34: 1250 | J34: 1300 | K34: 20881 | L34: 4200 | M34: 660 | N34: 600 | O34: 0 | P34: =SUM(D34:O34) -> 30501
C35: Travel / Holiday Trips | D35: 0 | E35: 2118 | F35: 1660 | G35: 43781 | H35: 0 | I35: 5225 | J35: 5450 | K35: 4190 | L35: 7525 | M35: 8870 | N35: 35770 | O35: 97450 | P35: =SUM(D35:O35) -> 212039
B36: Investments & Savings | C36: Gold Bhishi | D36: 0 | E36: 0 | F36: 0 | G36: 0 | H36: 0 | I36: 0 | J36: 0 | K36: 0 | L36: 0 | M36: 0 | N36: 0 | O36: 5000 | P36: =SUM(D36:O36) -> 5000 | Q36: =SUM(P36:P42) -> 5000
C37: IWish | D37: 0 | E37: 0 | F37: 0 | G37: 0 | H37: 0 | I37: 0 | J37: 0 | K37: 0 | L37: 0 | M37: 0 | N37: 0 | O37: 0 | P37: =SUM(D37:O37) -> 0
C38: Mutual Funds | D38: 0 | E38: 0 | F38: 0 | G38: 0 | H38: 0 | I38: 0 | J38: 0 | K38: 0 | L38: 0 | M38: 0 | N38: 0 | O38: 0 | P38: =SUM(D38:O38) -> 0
C39: Provident Fund | D39: 0 | E39: 0 | F39: 0 | G39: 0 | H39: 0 | I39: 0 | J39: 0 | K39: 0 | L39: 0 | M39: 0 | N39: 0 | O39: 0 | P39: =SUM(D39:O39) -> 0
C40: Post Office RD | D40: 0 | E40: 0 | F40: 0 | G40: 0 | H40: 0 | I40: 0 | J40: 0 | K40: 0 | L40: 0 | M40: 0 | N40: 0 | O40: 0 | P40: =SUM(D40:O40) -> 0
C41: Shares (Ashwini Shares) | D41: 0 | E41: 0 | F41: 0 | G41: 0 | H41: 0 | I41: 0 | J41: 0 | K41: 0 | L41: 0 | M41: 0 | N41: 0 | O41: 0 | P41: =SUM(D41:O41) -> 0
...

Sheet 2025
B2: Expense Category | C2: Expense Type | D2: Jan | E2: Feb | F2: Mar | G2: Apr | H2: May | I2: Jun | J2: Jul | K2: Aug | L2: Sep | M2: Oct | N2: Nov | O2: Dec | P2: Total Yearly | Q2: Expense Category Wise Yearly Total
B3: Essential Living | C3: Dmart | D3: 11386 | E3: 4800 | F3: 2128 | G3: 4965 | H3: 5847 | I3: 8676 | J3: 4656 | K3: 11600 | L3: 7000 | M3: 3467 | N3: 2100 | O3: 4000 | P3: =SUM(D3:O3) -> 70625 | Q3: =SUM(P3:P15) -> 593330
C4: Electricity | D4: 1210 | E4: 580 | F4: 590 | G4: 740 | H4: 0 | I4: 1480 | J4: 690 | K4: 690 | L4: 660 | M4: 730 | N4: 800 | O4: 640 | P4: =SUM(D4:O4) -> 8810
C5: Fuel | D5: 2850 | E5: 2850 | F5: 2850 | G5: 2850 | H5: 2850 | I5: 2850 | J5: 2850 | K5: 2850 | L5: 2850 | M5: 3070 | N5: 2850 | O5: 2850 | P5: =SUM(D5:O5) -> 34420
C6: Gas | D6: 1612 | E6: 1160 | F6: 806 | G6: 806 | H6: 856 | I6: 1712 | J6: 856 | K6: 856 | L6: 856 | M6: 0 | N6: 856 | O6: 856 | P6: =SUM(D6:O6) -> 11232
C7: Groceries | D7: 5958 | E7: 2436 | F7: 1905 | G7: 19465 | H7: 5750 | I7: 3037 | J7: 3755 | K7: 1190 | L7: 1400 | M7: 7087 | N7: 2600 | O7: 954 | P7: =SUM(D7:O7) -> 55537
C8: House Help / Maid Salary | D8: 2000 | E8: 4700 | F8: 2600 | G8: 1400 | H8: 4700 | I8: 5400 | J8: 6100 | K8: 6000 | L8: 6000 | M8: 6000 | N8: 3500 | O8: 5000 | P8: =SUM(D8:O8) -> 53400
C9: Internet / Wi-Fi | D9: 0 | E9: 0 | F9: 0 | G9: 3000 | H9: 0 | I9: 0 | J9: 0 | K9: 4200 | L9: 0 | M9: 0 | N9: 0 | O9: 0 | P9: =SUM(D9:O9) -> 7200
C10: LIC | D10: 4614 | E10: 4614 | F10: 37305 | G10: 0 | H10: 11832 | I10: 4512 | J10: 48411 | K10: 4614 | L10: 4614 | M10: 4512 | N10: 36151 | O10: 4512 | P10: =SUM(D10:O10) -> 165691
C11: Phone / Mobile Bill | D11: 498 | E11: 498 | F11: 2549 | G11: 300 | H11: 249 | I11: 449 | J11: 10299 | K11: 10377 | L11: 349 | M11: 2386 | N11: 2249 | O11: 3948 | P11: =SUM(D11:O11) -> 34151
C12: Property Tax | D12: 0 | E12: 0 | F12: 0 | G12: 0 | H12: 0 | I12: 6878 | J12: 0 | K12: 0 | L12: 0 | M12: 0 | N12: 0 | O12: 0 | P12: =SUM(D12:O12) -> 6878
C13: Rent | D13: 8500 | E13: 8500 | F13: 8500 | G13: 8500 | H13: 8500 | I13: 8500 | J13: 8500 | K13: 8500 | L13: 8500 | M13: 8500 | N13: 8500 | O13: 8500 | P13: =SUM(D13:O13) -> 102000
C14: Term Plan | D14: 2670 | E14: 2670 | F14: 30249 | G14: 0 | H14: 0 | I14: 0 | J14: 0 | K14: 0 | L14: 6204 | M14: 0 | N14: 0 | O14: 0 | P14: =SUM(D14:O14) -> 41793
C15: Water Bill | D15: 0 | E15: 0 | F15: 500 | G15: 0 | H15: 0 | I15: 0 | J15: 526 | K15: 0 | L15: 0 | M15: 0 | N15: 567 | O15: 0 | P15: =SUM(D15:O15) -> 1593
B16: Loans & Financial | C16: Credit Card Payments | D16: 0 | E16: 0 | F16: 23292 | G16: 20000 | H16: 55139 | I16: 0 | J16: 0 | K16: 75000 | L16: 27500 | M16: 0 | N16: 9690 | O16: 21000 | P16: =SUM(D16:O16) -> 231621 | Q16: =SUM(P16:P20) -> 1412287
C17: Gold Loan | D17: 0 | E17: 0 | F17: 0 | G17: 0 | H17: 0 | I17: 0 | J17: 0 | K17: 0 | L17: 0 | M17: 0 | N17: 0 | O17: 0 | P17: =SUM(D17:O17) -> 0
C18: Home Loan EMI | D18: 40000 | E18: 40000 | F18: 40000 | G18: 20000 | H18: 20000 | I18: 20000 | J18: 20000 | K18: 20000 | L18: 20000 | M18: 259000 | N18: 582507 | O18: 18359 | P18: =SUM(D18:O18) -> 1099866
C19: Money Returned to Friend/Family | D19: 3000 | E19: 5000 | F19: 0 | G19: 0 | H19: 60000 | I19: 10000 | J19: 0 | K19: 0 | L19: 0 | M19: 0 | N19: 2800 | O19: 0 | P19: =SUM(D19:O19) -> 80800
C20: Personal Loan | D20: 0 | E20: 0 | F20: 0 | G20: 0 | H20: 0 | I20: 0 | J20: 0 | K20: 0 | L20: 0 | M20: 0 | N20: 0 | O20: 0 | P20: =SUM(D20:O20) -> 0
B21: Family & Education | C21: Education Expenses (Sport material,Books, Uniforms, Shoes, Stationery, etc.) | D21: 0 | E21: 0 | F21: 1790 | G21: 0 | H21: 3441 | I21: 0 | J21: 0 | K21: 0 | L21: 0 | M21: 0 | N21: 0 | O21: 0 | P21: =SUM(D21:O21) -> 5231 | Q21: =SUM(P21:P25) -> 196831
C22: Family Support | D22: 5000 | E22: 0 | F22: 0 | G22: 0 | H22: 0 | I22: 0 | J22: 5000 | K22: 80000 | L22: 0 | M22: 0 | N22: 0 | O22: 0 | P22: =SUM(D22:O22) -> 90000
C23: Hobbies (Drawing, Bharatnatyam, etc.) | D23: 1000 | E23: 1000 | F23: 1000 | G23: 1000 | H23: 1000 | I23: 1000 | J23: 1000 | K23: 1000 | L23: 1000 | M23: 1000 | N23: 1000 | O23: 1000 | P23: =SUM(D23:O23) -> 12000
C24: School Fees | D24: 11000 | E24: 0 | F24: 0 | G24: 0 | H24: 0 | I24: 0 | J24: 0 | K24: 0 | L24: 20000 | M24: 0 | N24: 0 | O24: 0 | P24: =SUM(D24:O24) -> 31000
C25: Sports (Skating, Badminton, Cricket, Hockey) | D25: 8500 | E25: 4000 | F25: 11200 | G25: 9050 | H25: 5850 | I25: 2000 | J25: 3000 | K25: 3000 | L25: 3000 | M25: 9000 | N25: 0 | O25: 0 | P25: =SUM(D25:O25) -> 58600
B26: Health & Medical | C26: Doctors | D26: 13315 | E26: 0 | F26: 4400 | G26: 1500 | H26: 0 | I26: 0 | J26: 0 | K26: 381 | L26: 7530 | M26: 7450 | N26: 5800 | O26: 0 | P26: =SUM(D26:O26) -> 40376 | Q26: =SUM(P26:P27) -> 88189
C27: Medicine | D27: 0 | E27: 0 | F27: 9145 | G27: 1420 | H27: 1510 | I27: 0 | J27: 0 | K27: 3495 | L27: 25490 | M27: 6003 | N27: 750 | O27: 0 | P27: =SUM(D27:O27) -> 47813
B28: Lifestyle & Personal | C28: Clothing | D28: 1000 | E28: 1500 | F28: 5478 | G28: 400 | H28: 14758 | I28: 0 | J28: 2250 | K28: 5095 | L28: 0 | M28: 5282 | N28: 6397 | O28: 1100 | P28: =SUM(D28:O28) -> 43260 | Q28: =SUM(P28:P35) -> 505698
C29: Dining Out | D29: 6969 | E29: 4809 | F29: 4563 | G29: 6417 | H29: 7378 | I29: 51327 | J29: 9338 | K29: 9061 | L29: 4400 | M29: 12275 | N29: 7382 | O29: 5963 | P29: =SUM(D29:O29) -> 129882
C30: Gym | D30: 0 | E30: 0 | F30: 0 | G30: 0 | H30: 0 | I30: 12406 | J30: 35000 | K30: 7000 | L30: 7000 | M30: 7000 | N30: 3500 | O30: 7000 | P30: =SUM(D30:O30) -> 78906
C31: Hair / Cosmetics | D31: 2250 | E31: 750 | F31: 0 | G31: 0 | H31: 0 | I31: 2150 | J31: 0 | K31: 1700 | L31: 1550 | M31: 850 | N31: 1700 | O31: 0 | P31: =SUM(D31:O31) -> 10950
C32: Membership(Google,Netflix,Education,Youtube) | D32: 0 | E32: 0 | F32: 0 | G32: 0 | H32: 590 | I32: 0 | J32: 0 | K32: 699 | L32: 0 | M32: 448 | N32: 0 | O32: 0 | P32: =SUM(D32:O32) -> 1737
C33: Movies | D33: 0 | E33: 1287 | F33: 0 | G33: 0 | H33: 1260 | I33: 480 | J33: 0 | K33: 0 | L33: 260 | M33: 3570 | N33: 0 | O33: 0 | P33: =SUM(D33:O33) -> 6857
C34: Other Expenses | D34: 0 | E34: 650 | F34: 0 | G34: 0 | H34: 0 | I34: 1050 | J34: 0 | K34: 1800 | L34: 0 | M34: 8364 | N34: 1350 | O34: 11590 | P34: =SUM(D34:O34) -> 24804
C35: Travel / Holiday Trips | D35: 14670 | E35: 44291 | F35: 0 | G35: 0 | H35: 11210 | I35: 4700 | J35: 0 | K35: 0 | L35: 6120 | M35: 6513 | N35: 6920 | O35: 114878 | P35: =SUM(D35:O35) -> 209302
B36: Investments & Savings | C36: Gold Bhishi | D36: 5000 | E36: 5000 | F36: 5000 | G36: 5000 | H36: 5000 | I36: 5000 | J36: 5000 | K36: 5000 | L36: 5000 | M36: 5000 | N36: 5000 | O36: 5000 | P36: =SUM(D36:O36) -> 60000 | Q36: =SUM(P36:P42) -> 670411
C37: IWish | D37: 0 | E37: 0 | F37: 0 | G37: 0 | H37: 0 | I37: 0 | J37: 0 | K37: 0 | L37: 0 | M37: 0 | N37: 29911 | O37: 0 | P37: =SUM(D37:O37) -> 29911
C38: Mutual Funds | D38: 0 | E38: 0 | F38: 0 | G38: 0 | H38: 0 | I38: 0 | J38: 0 | K38: 0 | L38: 0 | M38: 0 | N38: 0 | O38: 0 | P38: =SUM(D38:O38) -> 0
C39: Provident Fund | D39: 0 | E39: 0 | F39: 0 | G39: 0 | H39: 0 | I39: 0 | J39: 0 | K39: 0 | L39: 0 | M39: 0 | N39: 0 | O39: 0 | P39: =SUM(D39:O39) -> 0
C40: Post Office RD | D40: 0 | E40: 0 | F40: 0 | G40: 0 | H40: 0 | I40: 0 | J40: 0 | K40: 0 | L40: 0 | M40: 0 | N40: 0 | O40: 0 | P40: =SUM(D40:O40) -> 0
C41: Shares (Ashwini Shares) | D41: 0 | E41: 0 | F41: 0 | G41: 0 | H41: 0 | I41: 0 | J41: 0 | K41: 0 | L41: 0 | M41: 0 | N41: 0 | O41: 0 | P41: =SUM(D41:O41) -> 0
...

Sheet 2026
B2: Expense Category | C2: Expense Type | D2: Jan | E2: Feb | F2: Mar | G2: Apr | H2: May | I2: Jun | J2: Jul | K2: Aug | L2: Sep | M2: Oct | N2: Nov | O2: Dec | P2: Total Yearly | Q2: Expense Category Wise Yearly Total
B3: Essential Living | C3: Dmart | D3: 2769 | E3: 516 | F3: 2835 | G3: 9105 | H3: 8600 | I3: 11500 | J3: 12000 | P3: =SUM(D3:O3) -> 47325 | Q3: =SUM(P3:P3:P17) -> 456562
C4: Electricity Bill | D4: 1250 | E4: 970 | F4: 1040 | G4: 1480 | H4: 640 | I4: 280 | J4: 2830 | P4: =SUM(D4:O4) -> 8490
C5: Fuel | D5: 2850 | E5: 4011 | F5: 2400 | G5: 2400 | H5: 2400 | I5: 2400 | J5: 2400 | P5: =SUM(D5:O5) -> 18861
C6: Gas | D6: 856 | E6: 856 | F6: 916 | G6: 916 | H6: 920 | I6: 920 | J6: 0 | P6: =SUM(D6:O6) -> 5384
C7: Fruits | D7: 4472 | E7: 4000 | F7: 1025 | G7: 15410 | H7: 2500 | I7: 3500 | J7: 4000 | P7: =SUM(D7:O7) -> 34907
C8: Vegetables | D8: 10000 | E8: 4096 | F8: 1755 | G8: 4479 | H8: 3600 | I8: 4500 | J8: 2500 | P8: =SUM(D8:O8) -> 30930
C9: House Help / Maid Salary | D9: 5000 | E9: 5900 | F9: 5900 | G9: 5900 | H9: 7607 | I9: 8000 | J9: 8000 | P9: =SUM(D9:O9) -> 46307
C10: Internet / Wi-Fi | D10: 0 | E10: 0 | F10: 1200 | G10: 1200 | H10: 0 | I10: 8000 | J10: 0 | P10: =SUM(D10:O10) -> 10400
C11: LIC | D11: 69390 | E11: 4512 | F11: 16522 | G11: 4512 | H11: 4512 | I11: 4512 | J11: 49512 | P11: =SUM(D11:O11) -> 153472
C12: Mobile Bill | D12: 0 | E12: 0 | F12: 1378 | G12: 0 | H12: 2450 | I12: 2450 | J12: 800 | P12: =SUM(D12:O12) -> 7078
C13: Maintenance / Society Charges / Property Tax | D13: 11830 | E13: 12330 | F13: 3388 | G13: 3885 | H13: 0 | I13: 0 | J13: 0 | P13: =SUM(D13:O13) -> 31433
C14: Term Plan | D14: 0 | E14: 0 | F14: 25635 | G14: 0 | H14: 0 | I14: 0 | J14: 7000 | P14: =SUM(D14:O14) -> 32635
C15: Family Support | D15: 0 | E15: 0 | F15: 1000 | G15: 0 | H15: 0 | I15: 25000 | J15: 0 | P15: =SUM(D15:O15) -> 26000
... C17: Water Bill | D17: 0 | E17: 0 | F17: 0 | G17: 0 | H17: 320 | I17: 0 | J17: 0 | P17: =SUM(D17:O17) -> 320
B18: Loans & Financial | C18: Credit Card Payments | D18: 0 | E18: 142704 | F18: 0 | G18: 0 | H18: 5150 | I18: 5150 | J18: 5150 | P18: =SUM(D18:O18) -> 158154 | Q18: =SUM(P18:P19) -> 557090
C19: Home / Gold / Personal Loan | D19: 18359 | E19: 18359 | F19: 80859 | G19: 80359 | H19: 67000 | I19: 67000 | J19: 67000 | P19: =SUM(D19:O19) -> 398936
B20: Education | C20: Education Expenses (Sport material,Books, Uniforms, Shoes, Stationery, etc.) | D20: 3200 | E20: 6180 | F20: 18852 | G20: 11769 | H20: 11000 | I20: 0 | J20: 2500 | P20: =SUM(D20:O20) -> 53501 | Q20: =SUM(P20:P23) -> 183959
C21: Hobbies (Drawing, Bharatnatyam, etc.) | D21: 1000 | E21: 1000 | F21: 1000 | G21: 2000 | H21: 2000 | I21: 2000 | J21: 2000 | P21: =SUM(D21:O21) -> 11000
C22: School Fees | D22: 45485 | E22: 20000 | F22: 0 | G22: 0 | H22: 0 | I22: 0 | J22: 36388 | P22: =SUM(D22:O22) -> 101873
C23: Sports (Skating, Badminton, Cricket, Hockey) | D23: 0 | E23: 6455 | F23: 5000 | G23: 1130 | H23: 5000 | I23: 0 | J23: 0 | P23: =SUM(D23:O23) -> 17585
B24: Health & Medical | C24: Doctors | D24: 133611 | E24: 500 | F24: 6650 | G24: 900 | H24: 3000 | I24: 2500 | J24: 12000 | P24: =SUM(D24:O24) -> 159161 | Q24: =SUM(P24:P26) -> 233128
C25: Lab Tests | D25: 0 | E25: 7500 | F25: 2500 | G25: 2500 | H25: 2000 | I25: 2000 | J25: 3000 | P25: =SUM(D25:O25) -> 19500
C26: Medicine | D26: 3776 | E26: 36379 | F26: 7120 | G26: 712 | H26: 2480 | I26: 1500 | J26: 2500 | P26: =SUM(D26:O26) -> 54467
B27: Lifestyle & Personal | C27: Clothing | D27: 0 | E27: 5369 | F27: 3000 | G27: 11324 | H27: 7800 | I27: 10000 | J27: 15000 | P27: =SUM(D27:O27) -> 52493 | Q27: =SUM(P27:P36) -> 335722
C28: Dining Out | D28: 11646 | E28: 13193 | F28: 9108 | G28: 20054 | H28: 15600 | I28: 12000 | J28: 18000 | P28: =SUM(D28:O28) -> 99601
C29: Gadgets / Electronics | D29: 0 | E29: 0 | F29: 6018 | G29: 4055 | H29: 0 | I29: 1500 | J29: 2300 | P29: =SUM(D29:O29) -> 13873
C30: Gym | D30: 7000 | E30: 0 | F30: 0 | G30: 0 | H30: 0 | I30: 0 | J30: 0 | P30: =SUM(D30:O30) -> 7000
C31: Hair / Cosmetics / Beauty Parlour | D31: 913 | E31: 2646 | F31: 913 | G31: 3410 | H31: 3400 | I31: 3400 | J31: 2500 | P31: =SUM(D31:O31) -> 17182
C32: Hobbies | D32: 0 | E32: 0 | F32: 900 | G32: 0 | H32: 3150 | I32: 4500 | J32: 1890 | P32: =SUM(D32:O32) -> 10440
C33: Membership(Google,Netflix,Education,Youtube) | D33: 598 | E33: 0 | F33: 0 | G33: 0 | H33: 0 | I33: 0 | J33: 2000 | P33: =SUM(D33:O33) -> 2598
C34: Movies | D34: 600 | E34: 600 | F34: 600 | G34: 0 | H34: 0 | I34: 0 | J34: 1500 | P34: =SUM(D34:O34) -> 3300
C35: Other Expenses | D35: 26212 | E35: 2291 | F35: 16793 | G35: 1245 | H35: 15360 | I35: 18560 | J35: 20000 | P35: =SUM(D35:O35) -> 100461
C36: Travel / Holiday Trips | D36: 0 | E36: 8210 | F36: 2573 | G36: 6531 | H36: 0 | I36: 6000 | J36: 5460 | P36: =SUM(D36:O36) -> 28774
B37: Investments & Savings | C37: IWish | D37: 0 | E37: 0 | F37: 0 | G37: 0 | H37: 0 | I37: 0 | J37: 0 | P37: =SUM(D37:O37) -> 0 | Q37: =SUM(P37:P40) -> 6000
C38: FD | D38: 0 | E38: 0 | F38: 0 | G38: 0 | H38: 0 | I38: 0 | J38: 0 | P38: =SUM(D38:O38) -> 0
C39: Mutual Funds | D39: 0 | E39: 0 | F39: 0 | G39: 0 | H39: 2000 | I39: 2000 | J39: 2000 | P39: =SUM(D39:O39) -> 6000
C40: SIP | D40: 0 | E40: 0 | F40: 0 | G40: 0 | H40: 0 | I40: 0 | J40: 0 | P40: =SUM(D40:O40) -> 0
B41: Miscellaneous | C41: Donations / Charity | D41: 500 | E41: 0 | F41: 500 | G41: 0 | H41: 0 | I41: 0 | J41: 0 | P41: =SUM(D41:O41) -> 1000 | Q41: =SUM(P41:P44) -> 72487
C42: Gifts / Celebrations | D42: 600 | E42: 0 | F42: 983 | G42: 2500 | H42: 0 | I42: 0 | J42: 0 | P42: =SUM(D42:O42) -> 4083
...

Sheet Total Expenses Sep-22 to Dec-25
B2: Expense Category | C2: Expense Type | D2: 2022 | E2: 2023 | F2: 2024 | G2: 2025 | H2: Total Yearly | I2: Expense Category Wise Yearly Total
B3: Essential Living | C3: Dmart | D3: 10485 | E3: 39742 | F3: 39743 | G3: ='2025'!P3 -> 70625 | H3: =SUM(D3:G3) -> 160595 | I3: =SUM(H3:H15) -> 1647336
C4: Electricity | D4: 2400 | E4: 11268 | F4: 10150 | G4: ='2025'!P4 -> 8810 | H4: =SUM(D4:G4) -> 32628
C5: Fuel | D5: 1500 | E5: 10380 | F5: 31400 | G5: ='2025'!P5 -> 34420 | H5: =SUM(D5:G5) -> 77700
C6: Gas | D6: 2112 | E6: 13892 | F6: 14096 | G6: ='2025'!P6 -> 11232 | H6: =SUM(D6:G6) -> 41332
C7: Groceries | D7: 1800 | E7: 22001 | F7: 33797 | G7: ='2025'!P7 -> 55537 | H7: =SUM(D7:G7) -> 113135
C8: House Help / Maid Salary | D8: 0 | E8: 0 | F8: 27750 | G8: ='2025'!P8 -> 53400 | H8: =SUM(D8:G8) -> 81150
C9: Internet / Wi-Fi | D9: 0 | E9: 7200 | F9: 7200 | G9: ='2025'!P9 -> 7200 | H9: =SUM(D9:G9) -> 21600
C10: LIC | D10: 56780 | E10: 160740 | F10: 174632 | G10: ='2025'!P10 -> 165691 | H10: =SUM(D10:G10) -> 557843
C11: Phone / Mobile Bill | D11: 1954 | E11: 5918 | F11: 43616 | G11: ='2025'!P11 -> 34151 | H11: =SUM(D11:G11) -> 85639
C12: Property Tax | D12: 0 | E12: 0 | F12: 21396 | G12: ='2025'!P12 -> 6878 | H12: =SUM(D12:G12) -> 28274
C13: Rent | D13: 30000 | E13: 95500 | F13: 100000 | G13: ='2025'!P13 -> 102000 | H13: =SUM(D13:G13) -> 327500
C14: Term Plan | D14: 10800 | E14: 32040 | F14: 32040 | G14: ='2025'!P14 -> 41793 | H14: =SUM(D14:G14) -> 116673
C15: Water Bill | D15: 0 | E15: 698 | F15: 976 | G15: ='2025'!P15 -> 1593 | H15: =SUM(D15:G15) -> 3267
B16: Loans & Financial | C16: Credit Card Payments | D16: 39680 | E16: 222927 | F16: 478947 | G16: ='2025'!P16 -> 231621 | H16: =SUM(D16:G16) -> 973175 | I16: =SUM(H16:H20) -> 4536242
C17: Gold Loan | D17: 0 | E17: 381628 | F17: 341389 | G17: ='2025'!P17 -> 0 | H17: =SUM(D17:G17) -> 723017
C18: Home Loan EMI | D18: 78000 | E18: 251000 | F18: 247800 | G18: ='2025'!P18 -> 1099866 | H18: =SUM(D18:G18) -> 1676666
C19: Money Returned to Friend/Family | D19: 175315 | E19: 502140 | F19: 81129 | G19: ='2025'!P19 -> 80800 | H19: =SUM(D19:G19) -> 839384
C20: Personal Loan | D20: 0 | E20: 135000 | F20: 189000 | G20: ='2025'!P20 -> 0 | H20: =SUM(D20:G20) -> 324000
B21: Family & Education | C21: Education Expenses (Sport material,Books, Uniforms, Shoes, Stationery, etc.) | D21: 0 | E21: 4775 | F21: 4555 | G21: ='2025'!P21 -> 5231 | H21: =SUM(D21:G21) -> 14561 | I21: =SUM(H21:H25) -> 652246
C22: Family Support | D22: 28000 | E22: 15000 | F22: 105500 | G22: ='2025'!P22 -> 90000 | H22: =SUM(D22:G22) -> 238500
C23: Hobbies (Drawing, Bharatnatyam, etc.) | D23: 4330 | E23: 10580 | F23: 13150 | G23: ='2025'!P23 -> 12000 | H23: =SUM(D23:G23) -> 40060
C24: School Fees | D24: 15000 | E24: 50000 | F24: 24000 | G24: ='2025'!P24 -> 31000 | H24: =SUM(D24:G24) -> 120000
C25: Sports (Skating, Badminton, Cricket, Hockey) | D25: 11000 | E25: 60600 | F25: 108925 | G25: ='2025'!P25 -> 58600 | H25: =SUM(D25:G25) -> 239125
B26: Health & Medical | C26: Doctors | D26: 0 | E26: 29460 | F26: 51981 | G26: ='2025'!P26 -> 40376 | H26: =SUM(D26:G26) -> 121817 | I26: =SUM(H26:H27) -> 309207
C27: Medicine | D27: 6500 | E27: 33280 | F27: 99797 | G27: ='2025'!P27 -> 47813 | H27: =SUM(D27:G27) -> 187390
B28: Lifestyle & Personal | C28: Clothing | D28: 1500 | E28: 16407 | F28: 48366 | G28: ='2025'!P28 -> 43260 | H28: =SUM(D28:G28) -> 109533 | I28: =SUM(H28:H35) -> 944778
C29: Dining Out | D29: 1770 | E29: 6660 | F29: 88316 | G29: ='2025'!P29 -> 129882 | H29: =SUM(D29:G29) -> 226628
C30: Gym | D30: 0 | E30: 0 | F30: 0 | G30: ='2025'!P30 -> 78906 | H30: =SUM(D30:G30) -> 78906
C31: Hair / Cosmetics | D31: 0 | E31: 380 | F31: 400 | G31: ='2025'!P31 -> 10950 | H31: =SUM(D31:G31) -> 11730
C32: Membership(Google,Netflix,Education,Youtube) | D32: 0 | E32: 1300 | F32: 6541 | G32: ='2025'!P32 -> 1737 | H32: =SUM(D32:G32) -> 9578
C33: Movies | D33: 0 | E33: 0 | F33: 0 | G33: ='2025'!P33 -> 6857 | H33: =SUM(D33:G33) -> 6857
C34: Other Expenses | D34: 0 | E34: 3100 | F34: 30501 | G34: ='2025'!P34 -> 24804 | H34: =SUM(D34:G34) -> 58405
C35: Travel / Holiday Trips | D35: 1650 | E35: 20150 | F35: 212039 | G35: ='2025'!P35 -> 209302 | H35: =SUM(D35:G35) -> 443141
B36: Investments & Savings | C36: Gold Bhishi | D36: 0 | E36: 0 | F36: 5000 | G36: ='2025'!P36 -> 60000 | H36: =SUM(D36:G36) -> 65000 | I36: =SUM(H36:H42) -> 717411
C37: IWish | D37: 0 | E37: 0 | F37: 0 | G37: ='2025'!P37 -> 29911 | H37: =SUM(D37:G37) -> 29911
C38: Mutual Funds | D38: 0 | E38: 0 | F38: 0 | G38: ='2025'!P38 -> 0 | H38: =SUM(D38:G38) -> 0
C39: Provident Fund | D39: 0 | E39: 0 | F39: 0 | G39: ='2025'!P39 -> 0 | H39: =SUM(D39:G39) -> 0
C40: Post Office RD | D40: 2000 | E40: 0 | F40: 0 | G40: ='2025'!P40 -> 0 | H40: =SUM(D40:G40) -> 2000
C41: Shares (Ashwini Shares) | D41: 0 | E41: 0 | F41: 0 | G41: ='2025'!P41 -> 0 | H41: =SUM(D41:G41) -> 0
...

Sheet Total Expenses Jan-26 to Till
B2: Expense Category | C2: Expense Type | D2: 2026 | E2: 2027 | F2: Total Yearly | G2: Expense Category Wise Yearly Total
B3: Essential Living | C3: Dmart
C4: Electricity Bill
C5: Fuel
C6: Gas
C7: Fruits
C8: Vegetables
C9: House Help / Maid Salary
C10: Internet / Wi-Fi
C11: LIC
C12: Mobile Bill
C13: Maintenance / Society Charges / Property Tax
C14: Term Plan
C15: Family Support
... C17: Water Bill
B18: Loans & Financial | C18: Credit Card Payments
C19: Home / Gold / Personal Loan
B20: Education | C20: Education Expenses (Sport material,Books, Uniforms, Shoes, Stationery, etc.)
C21: Hobbies (Drawing, Bharatnatyam, etc.)
C22: School Fees
C23: Sports (Skating, Badminton, Cricket, Hockey)
B24: Health & Medical | C24: Doctors
C25: Lab Tests
C26: Medicine
B27: Lifestyle & Personal | C27: Clothing
C28: Dining Out
C29: Gadgets / Electronics
C30: Gym
C31: Hair / Cosmetics / Beauty Parlour
C32: Hobbies
C33: Membership(Google,Netflix,Education,Youtube)
C34: Movies
C35: Other Expenses
C36: Travel / Holiday Trips
B37: Investments & Savings | C37: IWish
C38: FD
C39: Mutual Funds
C40: SIP
B41: Miscellaneous | C41: Donations / Charity
C42: Gifts / Celebrations
...
